<?xml version="1.0"?>
<robot xmlns:xacro="http://www.ros.org/wiki/xacro">
  <link name="world"/>

  <joint name="world_joint" type="fixed">
    <origin xyz="0.0 0.0 0.0" rpy="0.0 0.0 0.0"/>
    <parent link="world"/>
    <child link="base_link"/>
  </joint>

  <link name="base_link"/>

  <joint name="base_joint" type="fixed">
    <origin xyz="0.0 0.0 0.0058" rpy="0.0 0.0 0.0"/>
    <parent link="base_link"/>
    <child link="base_footprint"/>
    <axis xyz="0.0 0.0 0.0"/>
  </joint>
  <link
    name="base_footprint">
    <inertial>
      <origin
        xyz="0.0040721 -2.7299E-07 0.031134"
        rpy="0 0 0" />
      <mass
        value="0.071453" />
      <inertia
        ixx="2.4598E-05"
        ixy="1.7433E-10"
        ixz="1.5752E-07"
        iyy="2.7684E-05"
        iyz="5.3101E-11"
        izz="4.1569E-05" />
    </inertial>
    <visual>
      <origin
        xyz="0 0 0"
        rpy="0 0 0" />
      <geometry>
        <mesh
          filename="package://robot_arm/meshes/base_footprint.STL" />
      </geometry>
      <material
        name="">
        <color
          rgba="1 1 1 1" />
      </material>
    </visual>
    <collision>
      <origin
        xyz="0 0 0"
        rpy="0 0 0" />
      <geometry>
        <mesh
          filename="package://robot_arm/meshes/base_footprint.STL" />
      </geometry>
    </collision>
  </link>
  <link
    name="hombro_link">
    <inertial>
      <origin
        xyz="9.1858E-05 0.0042327 0.012701"
        rpy="0 0 0" />
      <mass
        value="0.080425" />
      <inertia
        ixx="1.5819E-05"
        ixy="2.8158E-07"
        ixz="-1.077E-08"
        iyy="2.1579E-05"
        iyz="-1.2522E-10"
        izz="3.147E-05" />
    </inertial>
    <visual>
      <origin
        xyz="0 0 0"
        rpy="0 0 0" />
      <geometry>
        <mesh
          filename="package://robot_arm/meshes/hombro_link.STL" />
      </geometry>
      <material
        name="">
        <color
          rgba="1 1 1 1" />
      </material>
    </visual>
    <collision>
      <origin
        xyz="0 0 0"
        rpy="0 0 0" />
      <geometry>
        <mesh
          filename="package://robot_arm/meshes/hombro_link.STL" />
      </geometry>
    </collision>
  </link>
  <joint
    name="hombro_joint"
    type="continuous">
    <origin
      xyz="0 0 0.062"
      rpy="0 0 0" />
    <parent
      link="base_footprint" />
    <child
      link="hombro_link" />
    <axis
      xyz="0 0 1" />
    <!-- <limit
      lower="-1"
      upper="1"
      effort="0.1"
      velocity="0.1" /> -->
    <dynamics
      damping="0.5"
      friction="1" />
  </joint>
  <link
    name="brazo_link">
    <inertial>
      <origin
        xyz="-0.00039648 0.086234 0.0023018"
        rpy="0 0 0" />
      <mass
        value="0.054387" />
      <inertia
        ixx="3.1805E-05"
        ixy="7.1623E-08"
        ixz="-1.4499E-08"
        iyy="6.3402E-06"
        iyz="1.5648E-07"
        izz="2.8995E-05" />
    </inertial>
    <visual>
      <origin
        xyz="0 0 0"
        rpy="0 0 0" />
      <geometry>
        <mesh
          filename="package://robot_arm/meshes/brazo_link.STL" />
      </geometry>
      <material
        name="">
        <color
          rgba="1 1 1 1" />
      </material>
    </visual>
    <collision>
      <origin
        xyz="0 0 0"
        rpy="0 0 0" />
      <geometry>
        <mesh
          filename="package://robot_arm/meshes/brazo_link.STL" />
      </geometry>
    </collision>
  </link>
  <joint
    name="brazo_joint"
    type="continuous">
    <origin
      xyz="0.010067 -0.015635 0.016"
      rpy="1.5708 0 0" />
    <parent
      link="hombro_link" />
    <child
      link="brazo_link" />
    <axis
      xyz="0 0 1" />
<!--     <limit
      lower="-1"
      upper="1"
      effort="0.1"
      velocity="0.1" /> -->
    <dynamics
      damping="0.5"
      friction="1" />
  </joint>
  <link
    name="ante_brazo_link">
    <inertial>
      <origin
        xyz="-0.00058855 0.08732 -0.0016105"
        rpy="0 0 0" />
      <mass
        value="0.045715" />
      <inertia
        ixx="3.628E-05"
        ixy="2.3254E-07"
        ixz="1.0002E-09"
        iyy="5.0337E-06"
        iyz="-1.5694E-07"
        izz="3.5144E-05" />
    </inertial>
    <visual>
      <origin
        xyz="0 0 0"
        rpy="0 0 0" />
      <geometry>
        <mesh
          filename="package://robot_arm/meshes/ante_brazo_link.STL" />
      </geometry>
      <material
        name="">
        <color
          rgba="0.79608 0.82353 0.93725 1" />
      </material>
    </visual>
    <collision>
      <origin
        xyz="0 0 0"
        rpy="0 0 0" />
      <geometry>
        <mesh
          filename="package://robot_arm/meshes/ante_brazo_link.STL" />
      </geometry>
    </collision>
  </link>
  <joint
    name="ante_brazo_joint"
    type="continuous">
    <origin
      xyz="-0.0005181 0.121 0.00048406"
      rpy="3.1416 -0.0055546 3.1416" />
    <parent
      link="brazo_link" />
    <child
      link="ante_brazo_link" />
    <axis
      xyz="0 0 1" />
    <!-- <limit
      lower="-1"
      upper="1"
      effort="0.1"
      velocity="0.1" /> -->
    <dynamics
      damping="0.5"
      friction="1" />
  </joint>
  <link
    name="muneca_link">
    <inertial>
      <origin
        xyz="-0.0098108 0.013581 -0.0060926"
        rpy="0 0 0" />
      <mass
        value="0.010179" />
      <inertia
        ixx="1.452E-06"
        ixy="4.1819E-07"
        ixz="1.0496E-11"
        iyy="1.1302E-06"
        iyz="-1.4291E-10"
        izz="1.2945E-06" />
    </inertial>
    <visual>
      <origin
        xyz="0 0 0"
        rpy="0 0 0" />
      <geometry>
        <mesh
          filename="package://robot_arm/meshes/muneca_link.STL" />
      </geometry>
      <material
        name="">
        <color
          rgba="0.79608 0.82353 0.93725 1" />
      </material>
    </visual>
    <collision>
      <origin
        xyz="0 0 0"
        rpy="0 0 0" />
      <geometry>
        <mesh
          filename="package://robot_arm/meshes/muneca_link.STL" />
      </geometry>
    </collision>
  </link>
  <joint
    name="muneca_joint"
    type="continuous">
    <origin
      xyz="0 0.122 0"
      rpy="0 0 0" />
    <parent
      link="ante_brazo_link" />
    <child
      link="muneca_link" />
    <axis
      xyz="0 0 1" />
    <!-- <limit
      lower="-1"
      upper="1"
      effort="0.1"
      velocity="0.1" /> -->
    <dynamics
      damping="0.5"
      friction="1" />
  </joint>
</robot>
